Workbook

Sheet Resumen
A1: Banca Online Integral
A4: ALCANCE FUNCIONAL Y DE CONTROL
A5: Canales | C5: Banca online y billetera digital con acceso reforzado.
A6: Operaciones | C6: Transferencias propias y a terceros, pagos QR, recargas y retiros.
A7: Créditos | C7: Simulación, solicitud, evaluación, desembolso y cronograma de préstamos.
A8: Control | C8: Partida doble, conciliación, fraude, cumplimiento, roles y auditoría.
A11: INDICADOR | B11: RESULTADO | D11: QUÉ DEMUESTRA EL PROYECTO
A12: Historias de usuario | B12: =COUNTA('Historias de Usuario'!$C$4:$C$29) -> 26 | D12: Seguridad | E12: KYC, MFA/biometría, mínimo privilegio y sesiones seguras.
A13: Historias Must | B13: =COUNTIF('Historias de Usuario'!$H$4:$H$32,"Must") -> 17 | D13: Dinero | E13: Validación, autorización, contabilización, liquidación y conciliación.
A14: Historias en MVP | B14: =COUNTIF('Historias de Usuario'!$J$4:$J$32,"Sí") -> 24 | D14: Transferencias | E14: Cuentas propias, terceros, beneficiarios y controles de duplicidad.
A15: Story Points del MVP | B15: =SUMIF('Historias de Usuario'!J4:J29,"Sí",'Historias de Usuario'!I4:I29) -> 160 | D15: Préstamos | E15: Evaluación separada del solicitante y desembolso solo tras aprobación.
A16: Sprints estimados | B16: 4 | D16: Supervisión | E16: Roles diferenciados para operaciones, fraude, crédito y cumplimiento.
A17: Épicas | B17: 7 | D17: Evidencia | E17: Trazabilidad completa; los movimientos se revierten, no se borran.

Sheet Historias de Usuario
A1: Historias de usuario — MVP Bancario (Sistema de Cuentas y Transacciones)
A3: ID | B3: Épica | C3: Sprint | D3: Módulo | E3: Rol | F3: Historia de Usuario | G3: Criterios de Aceptación | H3: Prioridad (MoSCoW) | I3: Story Points | J3: En MVP
A4: HU01 | B4: Épica 1 – Identidad, Biometría y KYC | C4: Sprint 1 | D4: Registro y KYC Biométrico | E4: Cliente | F4: Como cliente nuevo, quiero registrarme escaneando mi documento de identidad y validando mi rostro con Liveness Detection para aperturar mi cuenta digital de forma segura sin ir a una agencia. | G4: CA1: El sistema debe permitir capturar y leer los datos del documento de identidad mediante OCR con precisión mínima del 95%. CA2: El sistema debe ejecutar una prueba de vida (liveness detection) para descartar fotos, videos o máscaras antes de continuar el registro. CA3: El sistema debe comparar el rostro capturado contra la foto del documento y contra la base oficial (RENIEC), continuando solo si el match supera el umbral configurado. CA4: Si la validación falla, el sistema debe informar el motivo al cliente, permitir reintentos limitados y derivar el caso a revisión manual si persiste. | H4: Must | I4: 8 | J4: Sí
A5: HU02 | C5: Sprint 1 | D5: Verificación y Activación de Cuenta | E5: Cliente | F5: Como cliente nuevo, quiero confirmar mi registro mediante un código de verificación enviado a mi correo o celular para activar mi cuenta digital antes de iniciar sesión por primera vez. | G5: CA1: El sistema debe enviar un código de verificación de un solo uso (OTP) al correo o número celular registrado inmediatamente después de completado el KYC. CA2: El sistema debe validar el código ingresado y activar la cuenta solo si coincide y no ha expirado (máximo 10 minutos). CA3: El sistema debe permitir reenviar el código hasta 3 veces respetando un tiempo de espera entre solicitudes. CA4: Una vez activada la cuenta, el sistema debe notificar al cliente y habilitarlo para iniciar sesión con sus credenciales biométricas. | H5: Must | I5: 3 | J5: Sí
A6: HU03 | C6: Sprint 1 | D6: Autenticación BioFacial y Multi-factor | E6: Cliente | F6: Como cliente, quiero ingresar a la banca móvil mediante reconocimiento facial rápido o biométricos secundarios (Huella/PIN) para acceder sin recordar contraseñas complejas. | G6: CA1: El sistema debe permitir el ingreso mediante reconocimiento facial en menos de 1.5 segundos como método principal. CA2: El sistema debe ofrecer huella digital o PIN como método alternativo ante fallas del reconocimiento facial. CA3: El sistema debe bloquear temporalmente la cuenta tras 5 intentos fallidos consecutivos y notificar al cliente. CA4: El sistema debe cerrar automáticamente la sesión tras un período de inactividad configurado y exigir una nueva autenticación. | H6: Must | I6: 5 | J6: Sí
A7: HU04 | C7: Sprint 1 | D7: Recuperación de Cuenta con Biometría | E7: Cliente | F7: Como cliente, quiero recuperar mi acceso o desbloquear mi usuario mediante re-validación de biometría facial para restablecer mis credenciales de forma autónoma. | G7: CA1: El sistema debe permitir solicitar la recuperación de acceso desde la pantalla de login sin necesidad de contraseña previa. CA2: El sistema debe re-validar el rostro del cliente contra el patrón biométrico almacenado antes de habilitar el restablecimiento. CA3: El sistema debe permitir establecer una nueva contraseña o PIN únicamente después de una validación facial exitosa. CA4: El sistema debe notificar al cliente por correo y push que sus credenciales fueron restablecidas, incluyendo fecha y dispositivo. | H7: Should | I7: 5 | J7: Sí
A8: HU05 | B8: Épica 2 – Cuentas y Transacciones | C8: Sprint 1 | D8: Consolidado de Cuentas y Saldos | E8: Cliente | F8: Como cliente, quiero consultar saldos disponibles, fondos retenidos y movimientos en tiempo real para mantener control de mi patrimonio. | G8: CA1: El sistema debe mostrar en el dashboard todas las cuentas del cliente con su tipo, número enmascarado y saldo disponible. CA2: El sistema debe diferenciar el saldo contable del saldo disponible, incluyendo fondos retenidos. CA3: El sistema debe listar los movimientos recientes de cada cuenta en tiempo real al seleccionarla. CA4: El sistema debe permitir exportar el detalle de movimientos en un formato descargable (PDF o Excel). | H8: Must | I8: 5 | J8: Sí
A9: HU06 | C9: Sprint 1 | D9: Transferencias Propias e Interbancarias | E9: Cliente | F9: Como cliente, quiero transferir dinero entre mis cuentas y a terceros (mismo banco o interbancarias inmediatas) para mover mis fondos sin comisión oculta. | G9: CA1: El sistema debe permitir transferir fondos entre cuentas propias de forma inmediata y sin costo. CA2: El sistema debe permitir transferencias interbancarias mediante CCI/CCE, validando al titular antes de confirmar la operación. CA3: El sistema debe rechazar la operación sin afectar saldos cuando los fondos sean insuficientes. CA4: El sistema debe generar un comprobante descargable con fecha, monto, cuentas involucradas y número de operación. | H9: Must | I9: 8 | J9: Sí
A10: HU08 | C10: Sprint 2 | D10: Autorización Biométrico-Facial de Pagos Altamente Sensibles | E10: Cliente | F10: Como cliente, quiero confirmar transferencias de alto monto mediante escaneo facial instantáneo para garantizar que nadie transfiera sin mi presencia física, y que el sistema restrinja transacciones según mi perfil de riesgo. | G10: CA1: El sistema debe solicitar una validación facial adicional cuando el monto de la transferencia supere el umbral de seguridad parametrizado. CA2: El sistema debe restringir el envío de la transacción hasta que la biometría sea validada exitosamente. CA3: El sistema debe aplicar límites de transacción según el perfil de riesgo del cliente. CA4: El sistema debe registrar y notificar cualquier intento fallido de autorización biométrica como evento de seguridad. | H10: Must | I10: 8 | J10: Sí
A11: HU07 | C11: Sprint 2 | D11: Gestión de Beneficiarios Frecuentes | E11: Cliente | F11: Como cliente, quiero guardar y agrupar beneficiarios frecuentes con alias y fotos para reducir errores en transferencias recurrentes. | G11: CA1: El sistema debe permitir guardar un beneficiario con alias, foto y datos de cuenta tras una transferencia exitosa. CA2: El sistema debe permitir buscar y agrupar los beneficiarios guardados por alias o nombre. CA3: El sistema debe permitir configurar un límite de monto pre-aprobado por beneficiario frecuente. CA4: El sistema debe permitir editar o eliminar un beneficiario guardado en cualquier momento. | H11: Should | I11: 3 | J11: Sí
A12: HU09 | B12: Épica 3 – Créditos Digitales | C12: Sprint 2 | D12: Simulador Inteligente de Créditos | E12: Cliente | F12: Como cliente, quiero simular monto, plazo, tasa TCEA y cuota estimada para evaluar opciones de financiamiento antes de solicitar un crédito. | G12: CA1: El sistema debe calcular la cuota estimada según el monto, plazo y tasa TCEA ingresados por el cliente. CA2: El sistema debe mostrar un cronograma de pagos provisional con el detalle de capital e intereses. CA3: El sistema debe permitir incluir opcionalmente un seguro de desgravamen en la simulación. CA4: El sistema debe permitir descargar o compartir el resultado de la simulación. | H12: Should | I12: 5 | J12: Sí
A13: HU10 | C13: Sprint 2 | D13: Solicitud y Evaluación Crediticia Automática | E13: Cliente | F13: Como cliente, quiero solicitar un préstamo digital y autorizar la consulta en centrales de riesgo para recibir una respuesta de aprobación inmediata. | G13: CA1: El sistema debe permitir enviar una solicitud de préstamo solo si el cliente autoriza la consulta en centrales de riesgo. CA2: El sistema debe validar que la solicitud tenga todos los datos obligatorios antes de iniciar la evaluación. CA3: El sistema debe consultar el motor de riesgos y el score interno para generar una pre-calificación en minutos. CA4: El sistema debe notificar al cliente el resultado de la evaluación con un estado claro (aprobado, rechazado, en revisión). | H13: Must | I13: 8 | J13: Sí
A14: HU11 | C14: Sprint 2 | D14: Firma Digital de Contrato con Biometría Facial | E14: Cliente | F14: Como cliente, quiero firmar digitalmente mi contrato de préstamo validando mi rostro como consentimiento explícito para legalizar la operación sin papeleo. | G14: CA1: El sistema debe generar el contrato de préstamo con las condiciones aprobadas antes de solicitar la firma. CA2: El sistema debe validar el rostro del cliente como mecanismo de consentimiento explícito para firmar el contrato. CA3: El sistema debe adjuntar el token facial a la firma digital certificada del documento. CA4: El sistema debe enviar el pagaré y contrato sellado al correo del cliente tras la firma. | H14: Must | I14: 8 | J14: Sí
A15: HU12 | C15: Sprint 2 | D15: Desembolso Inmediato y Programación de Cuotas | E15: Cliente | F15: Como cliente, quiero recibir el desembolso directamente en mi cuenta elegida y visualizar mi cronograma de pagos definitivo para abonar mis cuotas a tiempo. | G15: CA1: El sistema debe acreditar el monto aprobado en la cuenta elegida por el cliente de forma inmediata tras la firma. CA2: El sistema debe generar el cronograma de pagos definitivo con fechas y montos de cada cuota. CA3: El sistema debe permitir habilitar el débito automático de las cuotas desde la cuenta elegida. CA4: El sistema debe notificar al cliente la fecha y monto de cada cuota próxima a vencer. | H15: Must | I15: 5 | J15: Sí
A16: HU13 | B16: Épica 4 – Billetera y Pagos QR | C16: Sprint 3 | D16: Billetera Digital e Interoperabilidad | E16: Cliente | F16: Como cliente, quiero vincular una tarjeta/cuenta a mi billetera digital para realizar pagos rápidos sin digitar claves en comercios. | G16: CA1: El sistema debe permitir vincular una tarjeta o cuenta del cliente a la billetera digital. CA2: El sistema debe procesar pagos en comercios sin requerir el ingreso de claves adicionales. CA3: El sistema debe operar de forma interoperable con las redes de pago de la industria. CA4: El sistema debe aplicar límites diarios configurables a las operaciones express de la billetera. | H16: Must | I16: 8 | J16: Sí
A17: HU14 | C17: Sprint 3 | D17: Generación y Cobro con QR Dinámico/Estático | E17: Comercio | F17: Como comercio, quiero generar códigos QR con monto y concepto específico para cobrar a mis clientes de forma ágil sin terminal POS físico. | G17: CA1: El sistema debe permitir generar un código QR con monto y concepto específico para cada cobro. CA2: El sistema debe permitir configurar la caducidad del código QR generado. CA3: El sistema debe garantizar la interoperabilidad del QR con otras billeteras y bancos. CA4: El sistema debe notificar al comercio mediante push en el momento en que se reciba el abono. | H17: Must | I17: 5 | J17: Sí
A18: HU15 | C18: Sprint 3 | D18: Lectura y Confirmación de Pago QR | E18: Cliente | F18: Como cliente, quiero escanear un código QR para verificar la información del comercio y pagar en un solo toque. | G18: CA1: El sistema debe leer el código QR y mostrar el nombre y monto del comercio antes de confirmar el pago. CA2: El sistema debe permitir completar el pago en un solo toque cuando el monto esté dentro del límite base. CA3: El sistema debe solicitar validación biométrica adicional si el monto excede el límite base configurado. CA4: El sistema debe rechazar el pago si el código QR está vencido o ha sido alterado. | H18: Must | I18: 5 | J18: Sí
A19: HU16 | C19: Sprint 3 | D19: Pago de Servicios y Recargas Express | E19: Cliente | F19: Como cliente, quiero pagar servicios básicos (luz, agua, internet) y recargar celulares desde la app para gestionar mis pagos en un solo lugar. | G19: CA1: El sistema debe permitir buscar un servicio (luz, agua, internet) por número de suministro. CA2: El sistema debe permitir recargar celulares seleccionando operador y monto directamente desde la app. CA3: El sistema debe enviar recordatorios de vencimiento de los servicios registrados por el cliente. CA4: El sistema debe generar un comprobante estructurado por cada pago o recarga realizada. | H19: Should | I19: 5 | J19: Sí
A20: HU17 | B20: Épica 5 – Motor Transaccional | C20: Sprint 3 | D20: Motor Transaccional en Tiempo Real | E20: Sistema | F20: Como sistema core bancario, quiero procesar transacciones con control de saldos, bloqueo de fondos y prevención de doble gasto para asegurar la consistencia operativa. | G20: CA1: El sistema debe validar el saldo disponible antes de ejecutar cada transacción. CA2: El sistema debe bloquear temporalmente los fondos comprometidos hasta la confirmación final de la operación. CA3: El sistema debe garantizar que ninguna transacción se procese dos veces ante reintentos o fallas de red. CA4: El sistema debe procesar cada transacción en un tiempo menor a 200 milisegundos bajo condiciones normales de carga. | H20: Must | I20: 13 | J20: Sí
A21: HU18 | C21: Sprint 3 | D21: Contabilidad en Libro Mayor (Ledger) de Partida Doble | E21: Sistema | F21: Como sistema contable, quiero registrar débitos y créditos con partida doble e identificador único universal (UUID) para mantener la integridad financiera. | G21: CA1: El sistema debe registrar cada operación con su respectivo débito y crédito en partida doble. CA2: El sistema debe asignar un identificador único universal (UUID) a cada asiento contable generado. CA3: El sistema debe garantizar que ningún asiento quede aplicado parcialmente si falla alguno de sus movimientos. CA4: El sistema debe ejecutar un cierre contable automatizado diario verificando que el balance esté cuadrado. | H21: Must | I21: 13 | J21: Sí
A22: HU19 | C22: Sprint 3 | D22: Conciliación Bancaria y Redes de Pago | E22: Analista de operaciones | F22: Como analista de operaciones, quiero ejecutar conciliaciones automáticas entre el banco, las redes externas y la billetera para detectar inconsistencias de liquidación. | G22: CA1: El sistema debe procesar automáticamente los archivos de compensación (clearing) recibidos de las redes externas. CA2: El sistema debe comparar las operaciones del banco contra las de las redes externas y la billetera para detectar diferencias. CA3: El sistema debe generar un reporte de inconsistencias detectadas durante la conciliación. CA4: El sistema debe habilitar un flujo de reclamos para las diferencias identificadas. | H22: Must | I22: 8 | J22: Sí
A23: HU20 | B23: Épica 6 – Fraude y Cumplimiento | C23: Sprint 4 | D23: Motor Antifraude por Reglas y Anomalías Biométricas | E23: Analista de fraude | F23: Como analista de fraude, quiero recibir alertas automáticas por intentos de suplantación facial, geolocalización atípica o transacciones inusuales para mitigar pérdidas. | G23: CA1: El sistema debe detectar y alertar intentos de suplantación facial (deepfake o spoofing) durante la autenticación. CA2: El sistema debe identificar geolocalización atípica o transacciones inusuales según el patrón de comportamiento del cliente. CA3: El sistema debe bloquear preventivamente una operación cuando se detecte una alerta de alto riesgo. CA4: El sistema debe mostrar las alertas generadas en un tablero para el analista de fraude. | H23: Must | I23: 8 | J23: Sí
A24: HU21 | C24: Sprint 4 | D24: Cumplimiento PLDFT / AML y Listas Restrictivas | E24: Oficial de cumplimiento | F24: Como oficial de cumplimiento, quiero cotejar clientes y transacciones contra listas restrictivas (OFAC, World-Check, PEP) para cumplir leyes antilavado. | G24: CA1: El sistema debe cotejar a cada cliente contra listas restrictivas (OFAC, World-Check, PEP) durante el onboarding. CA2: El sistema debe validar las transacciones en tiempo real contra las mismas listas restrictivas. CA3: El sistema debe generar un reporte de operación sospechosa (ROS) cuando se detecte una coincidencia relevante. CA4: El sistema debe registrar el resultado de cada validación para su posterior auditoría. | H24: Must | I24: 8 | J24: Sí
A25: HU22 | C25: Sprint 4 | D25: Notificaciones de Seguridad Multicanal | E25: Cliente | F25: Como cliente, quiero recibir alertas push y correos instantáneos por cada transacción o login biométrico para detectar cualquier actividad no autorizada. | G25: CA1: El sistema debe enviar una alerta push inmediata por cada transacción o inicio de sesión biométrico. CA2: El sistema debe enviar un correo electrónico con el mismo detalle de la alerta como respaldo. CA3: El sistema debe incluir en la alerta el dispositivo, hora y ubicación aproximada del evento. CA4: El sistema debe permitir al cliente reportar una actividad como no reconocida directamente desde la notificación. | H25: Should | I25: 3 | J25: Sí
A26: HU23 | C26: Sprint 4 | D26: Bitácora de Auditoría Inalterable (Audit Log) | E26: Auditor | F26: Como auditor, quiero consultar registros inalterables y con marca de tiempo de todos los cambios administrativos y verificaciones faciales para respaldar auditorías. | G26: CA1: El sistema debe registrar todo cambio administrativo y verificación facial en un log de solo lectura (append-only). CA2: El sistema debe aplicar un hash criptográfico a cada registro para garantizar su no repudio. CA3: El sistema debe permitir al auditor consultar los registros filtrando por fecha, usuario o tipo de evento. CA4: El sistema debe impedir la modificación o eliminación de cualquier registro ya almacenado. | H26: Could | I26: 5 | J26: No
A27: HU24 | B27: Épica 7 – Productos Avanzados | C27: Sprint 4 | D27: Cuentas Multidivisa y Meta de Ahorro Automático | E27: Cliente | F27: Como cliente, quiero aperturar bolsillos de ahorro y cuentas en USD/EUR para organizar mis metas con reglas de redondeo automático. | G27: CA1: El sistema debe permitir aperturar bolsillos de ahorro y cuentas en USD/EUR desde la app. CA2: El sistema debe permitir configurar reglas de redondeo automático hacia una meta de ahorro. CA3: El sistema debe calcular y acreditar automáticamente los rendimientos generados por cada bolsillo. CA4: El sistema debe permitir traspasos de fondos entre bolsillos y cuentas del mismo cliente. | H27: Should | I27: 5 | J27: Sí
A28: HU25 | C28: Sprint 4 | D28: Módulo de Cambio de Divisas Preferencial | E28: Cliente | F28: Como cliente, quiero comprar y vender divisas con tipo de cambio competitivo en tiempo real para optimizar mi dinero. | G28: CA1: El sistema debe mostrar una cotización de cambio en tiempo real congelada por 30 segundos antes de confirmar. CA2: El sistema debe aplicar un spread dinámico según el volumen de la operación. CA3: El sistema debe ejecutar la compra o venta de divisas de forma inmediata al confirmar la cotización vigente. CA4: El sistema debe rechazar la operación si la cotización congelada expiró antes de la confirmación. | H28: Should | I28: 8 | J28: Sí
A29: HU26 | C29: Sprint 4 | D29: Distribución Automática de Ingresos y Nómina | E29: Cliente | F29: Como cliente, quiero programar la distribución automática de mi sueldo en porcentajes apenas ingrese mi pago para presupuestar sin esfuerzo. | G29: CA1: El sistema debe permitir programar reglas de distribución automática por porcentaje sobre los ingresos recibidos. CA2: El sistema debe ejecutar la dispersión automática hacia facturas, ahorros e inversión al recibir un abono masivo. CA3: El sistema debe validar que la suma de los porcentajes configurados no exceda el 100%. CA4: El sistema debe notificar al cliente el detalle de cada distribución ejecutada. | H29: Could | I29: 8 | J29: No
I35: =SUM(I4:I29)-13 -> 160

Sheet Criterios Aceptacion
A1: Criterios de Aceptación — Sistema Bancario (Formato Gherkin: Dado / Cuando / Entonces)
A3: ID HU | B3: Área | C3: Requerimiento no funcional | D3: Criterio | E3: Dado | F3: Cuando | G3: Entonces | H3: Resultado esperado
A4: HU01 | B4: Registro y KYC Biométrico | C4: Seguridad / Rendimiento | D4: CA-01 | E4: Dado que el cliente escanea su documento de identidad físico | F4: Cuando el sistema procesa la captura mediante OCR | G4: Entonces se extraen los datos personales con una precisión mínima del 95% y se valida su vigencia | H4: Captura OCR válida
C5: Seguridad | D5: CA-02 | E5: Dado que los datos del documento fueron reconocidos | F5: Cuando el cliente realiza el escaneo facial en vivo | G5: Entonces el sistema ejecuta la prueba de vida (liveness detection) descartando intentos con fotos, videos o máscaras | H5: Liveness verificado
C6: Integridad / Confiabilidad | D6: CA-03 | E6: Dado que la prueba de vida es exitosa | F6: Cuando se contrasta el rostro con la foto del documento y la base oficial (RENIEC) | G6: Entonces se aprueba la coincidencia únicamente si el match supera el umbral de confianza configurado | H6: Match oficial confirmado
C7: Usabilidad / Trazabilidad | D7: CA-04 | E7: Dado que la validación biométrica no supera el umbral requerido | F7: Cuando se detecta la inconsistencia de identidad | G7: Entonces el sistema informa el motivo, permite reintentos limitados y deriva el caso a revisión manual si persiste | H7: Manejo de excepción KYC
A8: HU02 | B8: Verificación y Activación | C8: Seguridad | D8: CA-01 | E8: Dado que el cliente completó exitosamente la validación KYC | F8: Cuando el sistema procesa el alta de la solicitud | G8: Entonces se envía un código OTP de un solo uso de forma inmediata al correo y número celular registrados | H8: OTP generado y enviado
C9: Seguridad | D9: CA-02 | E9: Dado que el cliente recibe el código OTP | F9: Cuando lo ingresa dentro de los 10 minutos de vigencia | G9: Entonces el sistema valida el código, activa la cuenta digital y actualiza su estado a activa | H9: Cuenta activada
C10: Disponibilidad / Seguridad | D10: CA-03 | E10: Dado que el cliente no recibió el código o expiró | F10: Cuando solicita el reenvío del OTP | G10: Entonces el sistema permite hasta 3 solicitudes respetando un intervalo mínimo de espera entre envíos | H10: Reenvío de OTP controlado
C11: Usabilidad | D11: CA-04 | E11: Dado que la cuenta ha sido activada con éxito | F11: Cuando finaliza la pantalla de activación | G11: Entonces el sistema confirma al cliente y lo habilita para iniciar sesión con sus credenciales biométricas | H11: Acceso inicial habilitado
A12: HU03 | B12: Seguridad y Autenticación | C12: Rendimiento | D12: CA-01 | E12: Dado que el cliente tiene el reconocimiento biométrico activado | F12: Cuando abre la aplicación e inicia el escaneo facial | G12: Entonces el sistema valida la biometría y permite el acceso en menos de 1.5 segundos | H12: Acceso biométrico rápido
C13: Disponibilidad | D13: CA-02 | E13: Dado que las condiciones de luz impiden el match facial | F13: Cuando el reconocimiento biométrico no reconoce el rostro | G13: Entonces el sistema habilita el método secundario solicitando huella digital o PIN de contingencia | H13: Contingencia MFA
C14: Seguridad | D14: CA-03 | E14: Dado que se registran 5 intentos fallidos consecutivos de autenticación | F14: Cuando se procesa el quinto intento fallido | G14: Entonces la cuenta se bloquea temporalmente y se envía una notificación de alerta al cliente | H14: Ataque mitigado
C15: Seguridad | D15: CA-04 | E15: Dado que la aplicación permanece en segundo plano o sin interacción | F15: Cuando transcurre el tiempo configurado de inactividad (ej. 3 min) | G15: Entonces el sistema finaliza la sesión activa y solicita autenticación para reingresar | H15: Sesión protegida
A16: HU04 | B16: Recuperación de Cuenta | C16: Usabilidad | D16: CA-01 | E16: Dado que el usuario olvidó sus credenciales o tiene el acceso bloqueado | F16: Cuando selecciona 'Recuperar cuenta' desde la pantalla de login | G16: Entonces el sistema inicia el flujo solicitando únicamente su documento de identidad sin requerir clave previa | H16: Inicio autónomo
C17: Seguridad | D17: CA-02 | E17: Dado que el número de documento pertenece a un cliente activo | F17: Cuando el usuario efectúa el escaneo facial de prueba de vida | G17: Entonces el sistema re-valida el rostro contra el patrón biométrico original almacenado | H17: Re-validación biométrica
C18: Seguridad / Integridad | D18: CA-03 | E18: Dado que la re-validación biométrica resulta exitosa | F18: Cuando el usuario define su nueva contraseña o PIN | G18: Entonces el sistema actualiza las credenciales de inmediato en el repositorio seguro | H18: Restablecimiento de clave
C19: Auditoría / Seguridad | D19: CA-04 | E19: Dado que las credenciales han sido cambiadas | F19: Cuando concluye el proceso de restablecimiento | G19: Entonces el sistema notifica por push y correo detallando fecha, hora y dispositivo, revocando sesiones previas | H19: Notificación y revocación
A20: HU05 | B20: Cuentas y Saldos | C20: Usabilidad | D20: CA-01 | E20: Dado que el cliente tiene cuentas asociadas | F20: Cuando ingresa al dashboard principal | G20: Entonces se muestran todas sus cuentas con tipo de producto, número enmascarado y moneda | H20: Vista consolidada
C21: Integridad de datos | D21: CA-02 | E21: Dado que una cuenta posee transacciones retenidas | F21: Cuando el cliente consulta el detalle de la cuenta | G21: Entonces el sistema desglosa claramente el saldo contable respecto al saldo disponible neto | H21: Diferenciación de saldo
C22: Rendimiento | D22: CA-03 | E22: Dado que una cuenta registra nuevos movimientos | F22: Cuando el cliente selecciona la cuenta | G22: Entonces el listado de movimientos históricos y recientes se actualiza y muestra en tiempo real | H22: Movimientos en tiempo real
C23: Portabilidad | D23: CA-04 | E23: Dado que el usuario necesita sus transacciones para trámites | F23: Cuando presiona 'Exportar movimientos' | G23: Entonces el sistema genera y descarga un archivo estructurado en PDF o Excel con el reporte filtrado | H23: Reporte descargable
A24: HU06 | B24: Transferencias | C24: Rendimiento | D24: CA-01 | E24: Dado que ambas cuentas pertenecen al mismo cliente | F24: Cuando ingresa un monto válido y confirma la operación | G24: Entonces el débito y crédito se registran de forma inmediata y sin comisión entre cuentas propias | H24: Movimiento interno inmediato
C25: Integridad | D25: CA-02 | E25: Dado que el destinatario es de otra entidad financiera | F25: Cuando ingresa el código CCI y consulta la cuenta | G25: Entonces el sistema valida la titularidad antes de debitar y permite la transferencia interbancaria | H25: Validación CCI
C26: Seguridad / Integridad | D26: CA-03 | E26: Dado que el saldo disponible en la cuenta origen es menor al monto solicitado | F26: Cuando el cliente intenta confirmar la transferencia | G26: Entonces el sistema rechaza la operación sin modificar los saldos contables | H26: Saldo protegido
C27: Trazabilidad | D27: CA-04 | E27: Dado que la transferencia se ejecuta con éxito | F27: Cuando culmina la transacción en el sistema | G27: Entonces se genera un comprobante descargable con fecha, hora, monto, cuentas y número de operación único | H27: Comprobante oficial
A28: HU08 | B28: Seguridad Transaccional | C28: Seguridad | D28: CA-01 | E28: Dado que el monto de una transferencia supera el umbral parametrizado de seguridad | F28: Cuando el cliente presiona continuar para transferir | G28: Entonces el sistema exige obligatoriamente un escaneo facial biométrico para autorizar el cargo | H28: Exigencia biométrica
C29: Seguridad | D29: CA-02 | E29: Dado que la validación facial está pendiente | F29: Cuando no se ha completado el match satisfactoriamente | G29: Entonces el sistema restringe el envío y mantiene retenida la transacción sin ejecutar el débito | H29: Bloqueo preventivo
C30: Regulatorio / Riesgos | D30: CA-03 | E30: Dado que el cliente tiene un perfil de riesgo específico | F30: Cuando intenta realizar transacciones acumuladas en el día | G30: Entonces el sistema aplica los límites máximos diarios parametrizados para dicho perfil | H30: Límites aplicados
C31: Auditoría | D31: CA-04 | E31: Dado que un intento de autorización biométrica resulta fallido o sospechoso | F31: Cuando el sistema detecta la anomalía | G31: Entonces registra el evento de seguridad en auditoría y envía una alerta de advertencia al cliente | H31: Alerta de fraude
A32: HU07 | B32: Beneficiarios | C32: Usabilidad | D32: CA-01 | E32: Dado que una transferencia a un tercero concluyó exitosamente | F32: Cuando el cliente pulsa 'Guardar en frecuentes' | G32: Entonces el sistema almacena el contacto con alias personalizado, foto y datos bancarios asociados | H32: Beneficiario guardado
C33: Usabilidad | D33: CA-02 | E33: Dado que el cliente tiene múltiples contactos guardados | F33: Cuando escribe en el buscador de la agenda | G33: Entonces el sistema filtra en tiempo real por alias o nombre para una selección rápida | H33: Búsqueda predictiva
C34: Seguridad | D34: CA-03 | E34: Dado que el cliente configura su agenda de contactos | F34: Cuando establece un límite de monto pre-aprobado para un beneficiario frecuente | G34: Entonces el sistema permite transferencias ágiles hasta ese tope sin solicitar factores de seguridad adicionales | H34: Tope pre-aprobado
C35: Mantenibilidad | D35: CA-04 | E35: Dado que un beneficiario frecuente cambia de datos o ya no se requiere | F35: Cuando el cliente selecciona editar o eliminar el contacto | G35: Entonces el sistema actualiza o remueve el registro tras una confirmación de seguridad | H35: Gestión de agenda
A36: HU09 | B36: Créditos Digitales | C36: Precisión / Rendimiento | D36: CA-01 | E36: Dado que el usuario accede al simulador de créditos | F36: Cuando ingresa el monto, plazo y tasa de interés TCEA | G36: Entonces el sistema calcula y muestra instantáneamente la cuota mensual estimada | H36: Cálculo de cuota
C37: Transparencia | D37: CA-02 | E37: Dado que se calculó la cuota mensual | F37: Cuando el usuario despliega la tabla de pagos provisional | G37: Entonces el sistema detalla la amortización de capital, intereses devengados y fechas probables de pago | H37: Cronograma simulado
C38: Regulatorio | D38: CA-03 | E38: Dado que el préstamo requiere cobertura de desgravamen | F38: Cuando el cliente activa o desactiva la opción de seguro | G38: Entonces el sistema recalcula la cuota incorporando la prima correspondiente de manera transparente | H38: Seguro desgravamen
C39: Portabilidad | D39: CA-04 | E39: Dado que la simulación cumple con las expectativas del usuario | F39: Cuando presiona 'Descargar simulación' | G39: Entonces el sistema exporta un archivo PDF con las condiciones informativas sin carácter vinculante | H39: Cotización descargable
A40: HU10 | B40: Evaluación Crediticia | C40: Legal / Cumplimiento | D40: CA-01 | E40: Dado que el cliente completa los datos de la solicitud crediticia | F40: Cuando acepta explícitamente el tratamiento de datos y consulta en centrales de riesgo | G40: Entonces el sistema crea un expediente formal con ID único y estado 'En evaluación' | H40: Solicitud registrada
C41: Integridad | D41: CA-02 | E41: Dado que un campo obligatorio del formulario se encuentra vacío o con formato erróneo | F41: Cuando el usuario pulsa enviar solicitud | G41: Entonces el sistema indica claramente el error y no remite la evaluación al motor de crédito | H41: Validación de campos
...

Sheet Requerimientos Func-NoFunc
A1: Requerimientos Funcionales y No Funcionales por Historia de Usuario
A3: ID | B3: Épica | C3: Historia de Usuario | D3: Requerimientos Funcionales (RF) | E3: Requerimientos No Funcionales (RNF)
A4: HU01 | B4: Épica 1 – Identidad, Biometría y KYC | C4: Como cliente nuevo, quiero registrarme escaneando mi documento de identidad y validando mi rostro con Liveness Detection para aperturar mi cuenta digital de forma segura sin ir a una agencia. | D4: RF1: Capturar el documento de identidad (DNI/CE) mediante cámara y extraer los datos por OCR. RF2: Ejecutar prueba de vida (liveness detection) y comparar el rostro contra el documento y la base RENIEC. RF3: Crear automáticamente el usuario y la cuenta digital tras la validación exitosa del KYC. | E4: RNF1: Precisión de OCR ≥95% y de match facial ≥98% para minimizar falsos positivos/negativos. RNF2: El proceso completo de KYC no debe superar 60 segundos en condiciones normales de red. RNF3: Los datos biométricos y documentales deben cifrarse en tránsito y en reposo (TLS 1.2+/AES-256).
A5: HU27 | C5: Como cliente nuevo, quiero confirmar mi registro mediante un código de verificación enviado a mi correo o celular para activar mi cuenta digital antes de iniciar sesión por primera vez. | D5: RF1: Enviar un código OTP al correo o celular registrado al completar el KYC. RF2: Validar el OTP ingresado y activar la cuenta si es correcto y vigente. RF3: Permitir el reenvío del OTP con límite de intentos y tiempo de espera entre solicitudes. | E5: RNF1: El OTP debe expirar en un máximo de 10 minutos desde su generación. RNF2: El envío del OTP debe tener un SLA de entrega menor a 5 segundos. RNF3: El código debe ser de un solo uso y no reutilizable tras su validación o expiración.
A6: HU02 | C6: Como cliente, quiero ingresar a la banca móvil mediante reconocimiento facial rápido o biométricos secundarios (Huella/PIN) para acceder sin recordar contraseñas complejas. | D6: RF1: Permitir el inicio de sesión mediante reconocimiento facial como método principal. RF2: Ofrecer huella digital o PIN como método alternativo. RF3: Bloquear temporalmente la cuenta tras intentos fallidos consecutivos y cerrar sesión por inactividad. | E6: RNF1: La validación biométrica debe completarse en menos de 1.5 segundos. RNF2: El módulo de autenticación debe tener una disponibilidad mínima del 99.9%. RNF3: Los bloqueos por intentos fallidos deben registrarse sin exponer información sensible del cliente.
A7: HU04 | C7: Como cliente, quiero recuperar mi acceso o desbloquear mi usuario mediante re-validación de biometría facial para restablecer mis credenciales de forma autónoma. | D7: RF1: Permitir solicitar la recuperación de acceso desde el login sin contraseña previa. RF2: Re-validar el rostro del cliente contra el patrón biométrico almacenado. RF3: Permitir el restablecimiento de credenciales solo tras una validación facial exitosa. | E7: RNF1: El umbral de coincidencia facial para recuperación debe ser más estricto que el del login habitual. RNF2: El cambio de credenciales debe notificarse por un canal distinto en menos de 1 minuto. RNF3: Todo intento de recuperación debe quedar auditado con fecha, dispositivo y resultado.
A8: HU05 | B8: Épica 2 – Cuentas y Transacciones | C8: Como cliente, quiero consultar saldos disponibles, fondos retenidos y movimientos en tiempo real para mantener control de mi patrimonio. | D8: RF1: Mostrar todas las cuentas del cliente con tipo, número enmascarado y saldo disponible. RF2: Desglosar saldo contable, saldo disponible y fondos retenidos por cuenta. RF3: Permitir exportar el detalle de movimientos en PDF o Excel. | E8: RNF1: La consulta de saldos y movimientos debe responder en menos de 2 segundos. RNF2: El sistema debe soportar consultas concurrentes de miles de clientes sin degradar el tiempo de respuesta. RNF3: El número de cuenta debe mostrarse siempre enmascarado en pantalla.
A9: HU06 | C9: Como cliente, quiero transferir dinero entre mis cuentas y a terceros (mismo banco o interbancarias inmediatas) para mover mis fondos sin comisión oculta. | D9: RF1: Transferir fondos entre cuentas propias de forma inmediata y sin costo. RF2: Realizar transferencias interbancarias mediante CCI/CCE validando al titular antes de confirmar. RF3: Generar comprobante descargable con número de operación. | E9: RNF1: Las transferencias interbancarias deben ejecutarse en menos de 10 segundos. RNF2: El sistema debe garantizar idempotencia para evitar cobros duplicados ante reintentos de red. RNF3: Toda transferencia debe quedar trazada con fecha, hora y usuario para auditoría.
A10: HU08 | C10: Como cliente, quiero confirmar transferencias de alto monto mediante escaneo facial instantáneo para garantizar que nadie transfiera sin mi presencia física, y que el sistema restrinja transacciones según mi perfil de riesgo. | D10: RF1: Solicitar validación facial adicional cuando el monto supere el umbral de seguridad. RF2: Restringir el envío de la transacción hasta validar la biometría. RF3: Registrar y notificar los intentos fallidos de autorización como evento de seguridad. | E10: RNF1: La validación biométrica adicional no debe añadir más de 3 segundos al flujo de pago. RNF2: Los eventos de autorización fallida deben generar alerta en tiempo real al módulo antifraude. RNF3: El umbral de monto para exigir biometría debe ser configurable sin requerir despliegue de código.
A11: HU07 | C11: Como cliente, quiero guardar y agrupar beneficiarios frecuentes con alias y fotos para reducir errores en transferencias recurrentes. | D11: RF1: Registrar un beneficiario con alias, foto y datos de cuenta tras una transferencia exitosa. RF2: Buscar y agrupar beneficiarios guardados por alias o nombre. RF3: Editar o eliminar un beneficiario guardado. | E11: RNF1: La búsqueda de beneficiarios debe responder en menos de 1 segundo con hasta 100 registros. RNF2: Los datos de los beneficiarios deben almacenarse cifrados en la base de datos. RNF3: El límite pre-aprobado por beneficiario solo debe ser editable por el titular autenticado.
A12: HU09 | B12: Épica 3 – Créditos Digitales | C12: Como cliente, quiero simular monto, plazo, tasa TCEA y cuota estimada para evaluar opciones de financiamiento antes de solicitar un crédito. | D12: RF1: Calcular la cuota estimada según monto, plazo y tasa TCEA ingresados. RF2: Generar un cronograma de pagos provisional con capital e intereses. RF3: Permitir incluir opcionalmente un seguro de desgravamen en la simulación. | E12: RNF1: El cálculo de la simulación debe entregarse en menos de 1 segundo. RNF2: Las tasas y fórmulas usadas deben ser configurables por el área de productos sin cambios de código. RNF3: El simulador no debe generar ningún registro crediticio real sobre el cliente.
A13: HU10 | C13: Como cliente, quiero solicitar un préstamo digital y autorizar la consulta en centrales de riesgo para recibir una respuesta de aprobación inmediata. | D13: RF1: Enviar la solicitud de préstamo solo si el cliente autoriza la consulta en centrales de riesgo. RF2: Validar que la solicitud tenga todos los datos obligatorios antes de evaluarla. RF3: Consultar el motor de riesgos y el score interno para generar una pre-calificación. | E13: RNF1: La pre-calificación debe entregarse en un máximo de 5 minutos. RNF2: La integración con centrales de riesgo debe reintentar automáticamente ante caídas del servicio externo. RNF3: El resultado y su justificación deben quedar almacenados para fines regulatorios.
A14: HU11 | C14: Como cliente, quiero firmar digitalmente mi contrato de préstamo validando mi rostro como consentimiento explícito para legalizar la operación sin papeleo. | D14: RF1: Generar el contrato de préstamo con las condiciones aprobadas antes de la firma. RF2: Validar el rostro del cliente como mecanismo de consentimiento explícito. RF3: Enviar el pagaré y contrato sellado al correo del cliente tras la firma. | E14: RNF1: La firma digital debe cumplir estándares de firma electrónica reconocidos (no repudio). RNF2: El documento firmado debe estar disponible para el cliente en menos de 1 minuto. RNF3: El token facial asociado a la firma debe almacenarse cifrado y no reutilizarse en otra transacción.
A15: HU12 | C15: Como cliente, quiero recibir el desembolso directamente en mi cuenta elegida y visualizar mi cronograma de pagos definitivo para abonar mis cuotas a tiempo. | D15: RF1: Acreditar el monto aprobado en la cuenta elegida por el cliente. RF2: Generar el cronograma definitivo de cuotas. RF3: Habilitar el débito automático de las cuotas desde la cuenta elegida. | E15: RNF1: El desembolso debe acreditarse en menos de 30 segundos tras la firma del contrato. RNF2: El sistema debe notificar cada cuota próxima a vencer con al menos 2 días de anticipación. RNF3: El proceso de desembolso debe ser transaccional (todo o nada) para evitar acreditaciones parciales.
A16: HU13 | B16: Épica 4 – Billetera y Pagos QR | C16: Como cliente, quiero vincular una tarjeta/cuenta a mi billetera digital para realizar pagos rápidos sin digitar claves en comercios. | D16: RF1: Vincular una tarjeta o cuenta del cliente a la billetera digital. RF2: Procesar pagos en comercios sin requerir el ingreso de claves adicionales. RF3: Aplicar límites diarios configurables a las operaciones express. | E16: RNF1: El sistema debe ser interoperable con las redes de pago vigentes de la industria. RNF2: El pago con billetera debe completarse en menos de 3 segundos. RNF3: Los datos de la tarjeta/cuenta vinculada deben tokenizarse, sin almacenar el número completo.
A17: HU14 | C17: Como comercio, quiero generar códigos QR con monto y concepto específico para cobrar a mis clientes de forma ágil sin terminal POS físico. | D17: RF1: Generar un código QR con monto y concepto específico para cada cobro. RF2: Permitir configurar la caducidad del código QR generado. RF3: Notificar al comercio mediante push al recibir el abono. | E17: RNF1: El QR debe ser interoperable con otras billeteras y bancos (estándar QR interoperable). RNF2: La generación del QR debe completarse en menos de 1 segundo. RNF3: La notificación de abono debe entregarse en menos de 5 segundos desde la confirmación del pago.
A18: HU15 | C18: Como cliente, quiero escanear un código QR para verificar la información del comercio y pagar en un solo toque. | D18: RF1: Leer el código QR y mostrar el nombre y monto del comercio antes de confirmar el pago. RF2: Permitir completar el pago en un solo toque dentro del límite base. RF3: Rechazar el pago si el QR está vencido o alterado. | E18: RNF1: La lectura y validación del QR debe completarse en menos de 2 segundos. RNF2: El sistema debe validar la integridad del QR (firma/hash) para prevenir manipulación. RNF3: La validación biométrica adicional no debe añadir más de 3 segundos al flujo.
A19: HU16 | C19: Como cliente, quiero pagar servicios básicos (luz, agua, internet) y recargar celulares desde la app para gestionar mis pagos en un solo lugar. | D19: RF1: Buscar un servicio (luz, agua, internet) por número de suministro. RF2: Recargar celulares seleccionando operador y monto desde la app. RF3: Generar comprobante estructurado por cada pago o recarga. | E19: RNF1: La consulta del servicio debe responder en menos de 2 segundos. RNF2: El sistema debe integrar múltiples empresas de servicios y operadores sin cambios estructurales. RNF3: Los recordatorios de vencimiento deben enviarse con al menos 3 días de anticipación.
A20: HU17 | B20: Épica 5 – Motor Transaccional | C20: Como sistema core bancario, quiero procesar transacciones con control de saldos, bloqueo de fondos y prevención de doble gasto para asegurar la consistencia operativa. | D20: RF1: Validar el saldo disponible antes de ejecutar cada transacción. RF2: Bloquear temporalmente los fondos comprometidos hasta la confirmación final. RF3: Prevenir el doble procesamiento ante reintentos o fallas de red. | E20: RNF1: Cada transacción debe procesarse en menos de 200 milisegundos bajo carga normal. RNF2: El motor transaccional debe garantizar propiedades ACID en todas las operaciones. RNF3: El sistema debe soportar picos de carga (ej. fin de mes) sin degradar el SLA de procesamiento.
A21: HU18 | C21: Como sistema contable, quiero registrar débitos y créditos con partida doble e identificador único universal (UUID) para mantener la integridad financiera. | D21: RF1: Registrar cada operación con su respectivo débito y crédito en partida doble. RF2: Asignar un identificador único universal (UUID) a cada asiento contable. RF3: Ejecutar un cierre contable automatizado diario verificando que el balance esté cuadrado. | E21: RNF1: Ningún asiento debe quedar aplicado parcialmente ante una falla (atomicidad). RNF2: El cierre contable diario debe ejecutarse en una ventana definida sin afectar la operación diurna. RNF3: Los registros contables deben ser auditables y trazables por el periodo mínimo exigido por la regulación.
A22: HU19 | C22: Como analista de operaciones, quiero ejecutar conciliaciones automáticas entre el banco, las redes externas y la billetera para detectar inconsistencias de liquidación. | D22: RF1: Procesar automáticamente los archivos de compensación (clearing) de las redes externas. RF2: Comparar las operaciones del banco contra redes externas y billetera para detectar diferencias. RF3: Generar reporte de inconsistencias y habilitar el flujo de reclamos. | E22: RNF1: La conciliación diaria debe completarse antes del inicio de operaciones del siguiente día hábil. RNF2: El sistema debe procesar archivos de gran volumen sin pérdida de registros. RNF3: Las diferencias detectadas deben quedar documentadas con evidencia para su seguimiento.
A23: HU20 | B23: Épica 6 – Fraude y Cumplimiento | C23: Como analista de fraude, quiero recibir alertas automáticas por intentos de suplantación facial, geolocalización atípica o transacciones inusuales para mitigar pérdidas. | D23: RF1: Detectar intentos de suplantación facial (deepfake/spoofing) durante la autenticación. RF2: Identificar geolocalización atípica o transacciones inusuales según el comportamiento del cliente. RF3: Bloquear preventivamente una operación ante una alerta de alto riesgo y mostrarla en un tablero. | E23: RNF1: Las alertas de fraude deben generarse en tiempo real (menos de 1 segundo desde el evento). RNF2: El motor antifraude debe permitir actualizar sus reglas/modelos sin detener el servicio. RNF3: La tasa de falsos positivos debe mantenerse dentro del umbral definido por el negocio.
A24: HU21 | C24: Como oficial de cumplimiento, quiero cotejar clientes y transacciones contra listas restrictivas (OFAC, World-Check, PEP) para cumplir leyes antilavado. | D24: RF1: Cotejar a cada cliente contra listas restrictivas (OFAC, World-Check, PEP) en el onboarding. RF2: Validar las transacciones en tiempo real contra las mismas listas restrictivas. RF3: Generar un reporte de operación sospechosa (ROS) ante coincidencias relevantes. | E24: RNF1: El cotejo contra listas restrictivas debe ejecutarse en menos de 2 segundos por transacción. RNF2: Las listas restrictivas deben actualizarse de forma periódica y automática. RNF3: El resultado de cada validación debe registrarse para auditorías regulatorias (SBS/UIF).
A25: HU22 | C25: Como cliente, quiero recibir alertas push y correos instantáneos por cada transacción o login biométrico para detectar cualquier actividad no autorizada. | D25: RF1: Enviar una alerta push inmediata por cada transacción o inicio de sesión biométrico. RF2: Enviar un correo con el mismo detalle de la alerta como respaldo. RF3: Permitir al cliente reportar una actividad como no reconocida desde la notificación. | E25: RNF1: Las notificaciones deben entregarse en menos de 5 segundos desde el evento. RNF2: El sistema debe soportar múltiples canales sin perder mensajes ante la caída de un proveedor. RNF3: El reporte de actividad no reconocida debe escalar automáticamente al módulo antifraude.
A26: HU23 | C26: Como auditor, quiero consultar registros inalterables y con marca de tiempo de todos los cambios administrativos y verificaciones faciales para respaldar auditorías. | D26: RF1: Registrar todo cambio administrativo y verificación facial en un log append-only. RF2: Aplicar un hash criptográfico a cada registro almacenado. RF3: Permitir al auditor consultar registros filtrando por fecha, usuario o tipo de evento. | E26: RNF1: El log debe garantizar no repudio e impedir la modificación o eliminación de registros. RNF2: La bitácora debe conservar los registros por el periodo mínimo exigido por la regulación vigente. RNF3: Las consultas de auditoría no deben impactar el rendimiento de los sistemas transaccionales en producción.
A27: HU24 | B27: Épica 7 – Productos Avanzados | C27: Como cliente, quiero aperturar bolsillos de ahorro y cuentas en USD/EUR para organizar mis metas con reglas de redondeo automático. | D27: RF1: Aperturar bolsillos de ahorro y cuentas en USD/EUR desde la app. RF2: Configurar reglas de redondeo automático hacia una meta de ahorro. RF3: Traspasar fondos entre bolsillos y cuentas del mismo cliente. | E27: RNF1: El cálculo y acreditación de rendimientos debe ejecutarse de forma automática y periódica. RNF2: Los traspasos entre bolsillos deben reflejarse en el saldo en menos de 5 segundos. RNF3: El sistema debe soportar múltiples monedas sin errores de redondeo en las conversiones.
A28: HU25 | C28: Como cliente, quiero comprar y vender divisas con tipo de cambio competitivo en tiempo real para optimizar mi dinero. | D28: RF1: Mostrar la cotización de cambio de divisas en tiempo real. RF2: Congelar la cotización mostrada durante 30 segundos. RF3: Ejecutar la compra/venta de divisas al confirmar dentro del tiempo vigente. | E28: RNF1: La cotización debe actualizarse en tiempo real desde el proveedor de tipo de cambio. RNF2: El sistema debe rechazar automáticamente la operación si la cotización congelada expiró. RNF3: El spread aplicado debe ser configurable por el área de tesorería sin cambios de código.
A29: HU26 | C29: Como cliente, quiero programar la distribución automática de mi sueldo en porcentajes apenas ingrese mi pago para presupuestar sin esfuerzo. | D29: RF1: Permitir programar reglas de distribución automática por porcentaje sobre los ingresos. RF2: Ejecutar la dispersión automática hacia facturas, ahorros e inversión al recibir un abono masivo. RF3: Validar que la suma de los porcentajes configurados no exceda el 100%. | E29: RNF1: La dispersión automática debe ejecutarse en menos de 10 segundos tras detectar el abono. RNF2: El sistema debe notificar al cliente el detalle de cada distribución ejecutada en tiempo real. RNF3: Las reglas de distribución deben poder modificarse sin afectar distribuciones ya ejecutadas.

Sheet Backlog
A1: Product Backlog Priorizado
A3: Orden | B3: ID | C3: Épica | D3: Historia de Usuario | E3: Prioridad | F3: Story Points | G3: En MVP | H3: Sprint | I3: Dependencia | J3: Módulo | K3: Rol
A4: 1 | B4: HU01 | C4: Épica 1 – Identidad, Biometría y KYC | D4: Como cliente nuevo, quiero registrarme escaneando mi documento de identidad y validando mi rostro con Liveness Detection para aperturar mi cuenta digital de forma segura sin ir a una agencia. | E4: Must | F4: 8 | G4: Sí | H4: Sprint 1 | I4: Ninguna | J4: Registro y KYC Biométrico | K4: Cliente
A5: 2 | B5: HU02 | C5: Épica 1 – Identidad, Biometría y KYC | D5: Como cliente nuevo, quiero confirmar mi registro mediante un código de verificación enviado a mi correo o celular para activar mi cuenta digital antes de iniciar sesión por primera vez. | E5: Must | F5: 3 | G5: Sí | H5: Sprint 1 | I5: HU01 | J5: Verificación y Activación de Cuenta | K5: Cliente
A6: 3 | B6: HU03 | C6: Épica 1 – Identidad, Biometría y KYC | D6: Como cliente, quiero ingresar a la banca móvil mediante reconocimiento facial rápido o biométricos secundarios (Huella/PIN) para acceder sin recordar contraseñas complejas. | E6: Must | F6: 5 | G6: Sí | H6: Sprint 1 | I6: HU01-HU02 | J6: Autenticación BioFacial y Multi-factor | K6: Cliente
A7: 6 | B7: HU04 | C7: Épica 1 – Identidad, Biometría y KYC | D7: Como cliente, quiero recuperar mi acceso o desbloquear mi usuario mediante re-validación de biometría facial para restablecer mis credenciales de forma autónoma. | E7: Should | F7: 5 | G7: Sí | H7: Sprint 1 | I7: HU02-HU03 | J7: Recuperación de Cuenta con Biometría | K7: Cliente
A8: 4 | B8: HU05 | C8: Épica 2 – Cuentas y Transacciones | D8: Como cliente, quiero consultar saldos disponibles, fondos retenidos y movimientos en tiempo real para mantener control de mi patrimonio. | E8: Must | F8: 5 | G8: Sí | H8: Sprint 1 | I8: HU01-HU02 | J8: Consolidado de Cuentas y Saldos | K8: Cliente
A9: 5 | B9: HU06 | C9: Épica 2 – Cuentas y Transacciones | D9: Como cliente, quiero transferir dinero entre mis cuentas y a terceros (mismo banco o interbancarias inmediatas) para mover mis fondos sin comisión oculta. | E9: Must | F9: 8 | G9: Sí | H9: Sprint 1 | I9: HU05 | J9: Transferencias Propias e Interbancarias | K9: Cliente
A10: 11 | B10: HU07 | C10: Épica 2 – Cuentas y Transacciones | D10: Como cliente, quiero guardar y agrupar beneficiarios frecuentes con alias y fotos para reducir errores en transferencias recurrentes. | E10: Should | F10: 3 | G10: Sí | H10: Sprint 2 | I10: HU06 | J10: Gestión de Beneficiarios Frecuentes | K10: Cliente
A11: 7 | B11: HU08 | C11: Épica 2 – Cuentas y Transacciones | D11: Como cliente, quiero confirmar transferencias de alto monto mediante escaneo facial instantáneo para garantizar que nadie transfiera sin mi presencia física, y que el sistema restrinja transacciones según mi perfil de riesgo. | E11: Must | F11: 8 | G11: Sí | H11: Sprint 2 | I11: HU02, HU06 | J11: Autorización Biométrico-Facial de Pagos Altamente Sensibles | K11: Cliente
A12: 12 | B12: HU09 | C12: Épica 3 – Créditos Digitales | D12: Como cliente, quiero simular monto, plazo, tasa TCEA y cuota estimada para evaluar opciones de financiamiento antes de solicitar un crédito. | E12: Should | F12: 5 | G12: Sí | H12: Sprint 2 | I12: HU05 | J12: Simulador Inteligente de Créditos | K12: Cliente
A13: 8 | B13: HU10 | C13: Épica 3 – Créditos Digitales | D13: Como cliente, quiero solicitar un préstamo digital y autorizar la consulta en centrales de riesgo para recibir una respuesta de aprobación inmediata. | E13: Must | F13: 8 | G13: Sí | H13: Sprint 2 | I13: HU01, HU09 | J13: Solicitud y Evaluación Crediticia Automática | K13: Cliente
A14: 9 | B14: HU11 | C14: Épica 3 – Créditos Digitales | D14: Como cliente, quiero firmar digitalmente mi contrato de préstamo validando mi rostro como consentimiento explícito para legalizar la operación sin papeleo. | E14: Must | F14: 8 | G14: Sí | H14: Sprint 2 | I14: HU10 | J14: Firma Digital de Contrato con Biometría Facial | K14: Cliente
A15: 10 | B15: HU12 | C15: Épica 3 – Créditos Digitales | D15: Como cliente, quiero recibir el desembolso directamente en mi cuenta elegida y visualizar mi cronograma de pagos definitivo para abonar mis cuotas a tiempo. | E15: Must | F15: 5 | G15: Sí | H15: Sprint 2 | I15: HU05, HU11 | J15: Desembolso Inmediato y Programación de Cuotas | K15: Cliente
... A18: 15 | B18: HU15 | C18: Épica 4 – Billetera y Pagos QR | D18: Como cliente, quiero escanear un código QR para verificar la información del comercio y pagar en un solo toque. | E18: Must | F18: 5 | G18: Sí | H18: Sprint 3 | I18: HU14, HU17-HU18 | J18: Lectura y Confirmación de Pago QR | K18: Cliente
A19: 19 | B19: HU16 | C19: Épica 4 – Billetera y Pagos QR | D19: Como cliente, quiero pagar servicios básicos (luz, agua, internet) y recargar celulares desde la app para gestionar mis pagos en un solo lugar. | E19: Should | F19: 5 | G19: Sí | H19: Sprint 3 | I19: HU05, HU17-HU18 | J19: Pago de Servicios y Recargas Express
A20: 16 | B20: HU17 | C20: Épica 5 – Motor Transaccional | D20: Como sistema core bancario, quiero procesar transacciones con control de saldos, bloqueo de fondos y prevención de doble gasto para asegurar la consistencia operativa. | E20: Must | F20: 13 | G20: Sí | H20: Sprint 3 | I20: HU02, HU05 | J20: Motor Transaccional en Tiempo Real | K20: Sistema
A21: 17 | B21: HU18 | C21: Épica 5 – Motor Transaccional | D21: Como sistema contable, quiero registrar débitos y créditos con partida doble e identificador único universal (UUID) para mantener la integridad financiera. | E21: Must | F21: 13 | G21: Sí | H21: Sprint 3 | I21: HU17 | J21: Contabilidad en Libro Mayor (Ledger) de Partida Doble | K21: Analista de operaciones
A22: 18 | B22: HU19 | C22: Épica 5 – Motor Transaccional | D22: Como analista de operaciones, quiero ejecutar conciliaciones automáticas entre el banco, las redes externas y la billetera para detectar inconsistencias de liquidación. | E22: Must | F22: 8 | G22: Sí | H22: Sprint 3 | I22: HU18 | J22: Conciliación Bancaria y Redes de Pago | K22: Cliente
A23: 20 | B23: HU20 | C23: Épica 6 – Fraude y Cumplimiento | D23: Como analista de fraude, quiero recibir alertas automáticas por intentos de suplantación facial, geolocalización atípica o transacciones inusuales para mitigar pérdidas. | E23: Must | F23: 8 | G23: Sí | H23: Sprint 4 | I23: HU17 | J23: Motor Antifraude por Reglas y Anomalías Biométricas | K23: Analista de fraude
A24: 21 | B24: HU21 | C24: Épica 6 – Fraude y Cumplimiento | D24: Como oficial de cumplimiento, quiero cotejar clientes y transacciones contra listas restrictivas (OFAC, World-Check, PEP) para cumplir leyes antilavado. | E24: Must | F24: 8 | G24: Sí | H24: Sprint 4 | I24: HU03, HU20 | J24: Cumplimiento PLDFT / AML y Listas Restrictivas | K24: Oficial de cumplimiento
A25: 22 | B25: HU22 | C25: Épica 6 – Fraude y Cumplimiento | D25: Como cliente, quiero recibir alertas push y correos instantáneos por cada transacción o login biométrico para detectar cualquier actividad no autorizada. | E25: Should | F25: 3 | G25: Sí | H25: Sprint 4 | I25: HU17 | J25: Notificaciones de Seguridad Multicanal | K25: Cliente
A26: 21 | B26: HU22 | C26: FRAUDE, AUDITORÍA Y CUMPLIMIENTO | D26: Como cliente, quiero recibir una constancia y alerta inmediata por cada movimiento para detectar actividad desconocida. | E26: Should | F26: 3 | G26: Sí | H26: Sprint 4 | I26: HU17 | J26: Notificaciones | K26: Cliente
A27: 25 | B27: HU23 | C27: Épica 6 – Fraude y Cumplimiento | D27: Como auditor, quiero consultar registros inalterables y con marca de tiempo de todos los cambios administrativos y verificaciones faciales para respaldar auditorías. | E27: Could | F27: 5 | G27: No | H27: Sprint 4 | I27: HU03, HU18, HU21 | J27: Bitácora de Auditoría Inalterable (Audit Log) | K27: Auditor
A28: 23 | B28: HU24 | C28: Épica 7 – Productos Avanzados | D28: Como cliente, quiero aperturar bolsillos de ahorro y cuentas en USD/EUR para organizar mis metas con reglas de redondeo automático. | E28: Should | F28: 5 | G28: Sí | H28: Sprint 4 | I28: HU05, HU17-HU18 | J28: Cuentas Multidivisa y Meta de Ahorro Automático | K28: Cliente
A29: 24 | B29: HU25 | C29: Épica 7 – Productos Avanzados | D29: Como cliente, quiero comprar y vender divisas con tipo de cambio competitivo en tiempo real para optimizar mi dinero. | E29: Should | F29: 8 | G29: Sí | H29: Sprint 4 | I29: HU05, HU17-HU18 | J29: Módulo de Cambio de Divisas Preferencial | K29: Cliente
